WARNING 2023-10-19 15:29:34,648 log Not Found: /
WARNING 2023-10-19 15:29:34,651 basehttp "GET / HTTP/1.1" 404 2163
WARNING 2023-10-19 15:30:03,700 log Not Found: /
WARNING 2023-10-19 15:30:03,703 basehttp "GET / HTTP/1.1" 404 2163
WARNING 2023-10-19 15:30:21,570 log Not Found: /
WARNING 2023-10-19 15:30:21,573 basehttp "GET / HTTP/1.1" 404 2163
WARNING 2023-10-19 15:37:57,997 log Bad Request: /v1/student/
WARNING 2023-10-19 15:37:58,038 basehttp "POST /v1/student/ HTTP/1.1" 400 62
WARNING 2023-10-19 15:39:40,473 log Method Not Allowed: /v1/student/
WARNING 2023-10-19 15:39:40,477 basehttp "PATCH /v1/student/ HTTP/1.1" 405 42
WARNING 2023-10-19 15:39:53,716 log Method Not Allowed: /v1/student/
WARNING 2023-10-19 15:39:53,720 basehttp "PUT /v1/student/ HTTP/1.1" 405 40
WARNING 2023-10-19 15:40:43,309 log Method Not Allowed: /v1/student/1/
WARNING 2023-10-19 15:40:43,311 basehttp "GET /v1/student/1/ HTTP/1.1" 405 40
WARNING 2023-10-19 15:40:54,940 log Method Not Allowed: /v1/student/1/
WARNING 2023-10-19 15:40:54,946 basehttp "GET /v1/student/1/ HTTP/1.1" 405 40
WARNING 2023-10-19 15:41:47,192 log Bad Request: /v1/student/
WARNING 2023-10-19 15:41:47,194 basehttp "POST /v1/student/ HTTP/1.1" 400 52
WARNING 2023-10-19 15:52:36,011 log Not Found: /
WARNING 2023-10-19 15:52:36,026 basehttp "GET / HTTP/1.1" 404 2163
WARNING 2023-10-19 15:55:50,973 log Not Found: /
WARNING 2023-10-19 15:55:50,973 basehttp "GET / HTTP/1.1" 404 2163
WARNING 2023-10-19 16:05:00,857 log Not Found: /
WARNING 2023-10-19 16:05:00,858 basehttp "GET / HTTP/1.1" 404 2163
ERROR 2023-10-19 16:05:07,508 log Internal Server Error: /v1/
Traceback (most recent call last):
  File "C:\Users\Admin\AppData\Local\Programs\Python\Python311\Lib\site-packages\django\contrib\sessions\backends\base.py", line 187, in _get_session
    return self._session_cache
           ^^^^^^^^^^^^^^^^^^^
AttributeError: 'SessionStore' object has no attribute '_session_cache'

During handling of the above exception, another exception occurred:

Traceback (most recent call last):
  File "C:\Users\Admin\AppData\Local\Programs\Python\Python311\Lib\site-packages\django\db\backends\utils.py", line 89, in _execute
    return self.cursor.execute(sql, params)
           ^^^^^^^^^^^^^^^^^^^^^^^^^^^^^^^^
  File "C:\Users\Admin\AppData\Local\Programs\Python\Python311\Lib\site-packages\django\db\backends\mysql\base.py", line 75, in execute
    return self.cursor.execute(query, args)
           ^^^^^^^^^^^^^^^^^^^^^^^^^^^^^^^^
  File "C:\Users\Admin\AppData\Local\Programs\Python\Python311\Lib\site-packages\MySQLdb\cursors.py", line 206, in execute
    res = self._query(query)
          ^^^^^^^^^^^^^^^^^^
  File "C:\Users\Admin\AppData\Local\Programs\Python\Python311\Lib\site-packages\MySQLdb\cursors.py", line 319, in _query
    db.query(q)
  File "C:\Users\Admin\AppData\Local\Programs\Python\Python311\Lib\site-packages\MySQLdb\connections.py", line 254, in query
    _mysql.connection.query(self, query)
MySQLdb.ProgrammingError: (1146, "Table 'logging.django_session' doesn't exist")

The above exception was the direct cause of the following exception:

Traceback (most recent call last):
  File "C:\Users\Admin\AppData\Local\Programs\Python\Python311\Lib\site-packages\django\core\handlers\exception.py", line 55, in inner
    response = get_response(request)
               ^^^^^^^^^^^^^^^^^^^^^
  File "C:\Users\Admin\AppData\Local\Programs\Python\Python311\Lib\site-packages\django\core\handlers\base.py", line 197, in _get_response
    response = wrapped_callback(request, *callback_args, **callback_kwargs)
               ^^^^^^^^^^^^^^^^^^^^^^^^^^^^^^^^^^^^^^^^^^^^^^^^^^^^^^^^^^^^
  File "C:\Users\Admin\AppData\Local\Programs\Python\Python311\Lib\site-packages\django\views\decorators\csrf.py", line 56, in wrapper_view
    return view_func(*args, **kwargs)
           ^^^^^^^^^^^^^^^^^^^^^^^^^^
  File "C:\Users\Admin\AppData\Local\Programs\Python\Python311\Lib\site-packages\django\views\generic\base.py", line 104, in view
    return self.dispatch(request, *args, **kwargs)
           ^^^^^^^^^^^^^^^^^^^^^^^^^^^^^^^^^^^^^^^
  File "C:\Users\Admin\AppData\Local\Programs\Python\Python311\Lib\site-packages\rest_framework\views.py", line 509, in dispatch
    response = self.handle_exception(exc)
               ^^^^^^^^^^^^^^^^^^^^^^^^^^
  File "C:\Users\Admin\AppData\Local\Programs\Python\Python311\Lib\site-packages\rest_framework\views.py", line 469, in handle_exception
    self.raise_uncaught_exception(exc)
  File "C:\Users\Admin\AppData\Local\Programs\Python\Python311\Lib\site-packages\rest_framework\views.py", line 480, in raise_uncaught_exception
    raise exc
  File "C:\Users\Admin\AppData\Local\Programs\Python\Python311\Lib\site-packages\rest_framework\views.py", line 497, in dispatch
    self.initial(request, *args, **kwargs)
  File "C:\Users\Admin\AppData\Local\Programs\Python\Python311\Lib\site-packages\rest_framework\views.py", line 414, in initial
    self.perform_authentication(request)
  File "C:\Users\Admin\AppData\Local\Programs\Python\Python311\Lib\site-packages\rest_framework\views.py", line 324, in perform_authentication
    request.user
  File "C:\Users\Admin\AppData\Local\Programs\Python\Python311\Lib\site-packages\rest_framework\request.py", line 227, in user
    self._authenticate()
  File "C:\Users\Admin\AppData\Local\Programs\Python\Python311\Lib\site-packages\rest_framework\request.py", line 380, in _authenticate
    user_auth_tuple = authenticator.authenticate(self)
                      ^^^^^^^^^^^^^^^^^^^^^^^^^^^^^^^^
  File "C:\Users\Admin\AppData\Local\Programs\Python\Python311\Lib\site-packages\rest_framework\authentication.py", line 127, in authenticate
    if not user or not user.is_active:
  File "C:\Users\Admin\AppData\Local\Programs\Python\Python311\Lib\site-packages\django\utils\functional.py", line 266, in inner
    self._setup()
  File "C:\Users\Admin\AppData\Local\Programs\Python\Python311\Lib\site-packages\django\utils\functional.py", line 419, in _setup
    self._wrapped = self._setupfunc()
                    ^^^^^^^^^^^^^^^^^
  File "C:\Users\Admin\AppData\Local\Programs\Python\Python311\Lib\site-packages\django\contrib\auth\middleware.py", line 25, in <lambda>
    request.user = SimpleLazyObject(lambda: get_user(request))
                                            ^^^^^^^^^^^^^^^^^
  File "C:\Users\Admin\AppData\Local\Programs\Python\Python311\Lib\site-packages\django\contrib\auth\middleware.py", line 11, in get_user
    request._cached_user = auth.get_user(request)
                           ^^^^^^^^^^^^^^^^^^^^^^
  File "C:\Users\Admin\AppData\Local\Programs\Python\Python311\Lib\site-packages\django\contrib\auth\__init__.py", line 191, in get_user
    user_id = _get_user_session_key(request)
              ^^^^^^^^^^^^^^^^^^^^^^^^^^^^^^
  File "C:\Users\Admin\AppData\Local\Programs\Python\Python311\Lib\site-packages\django\contrib\auth\__init__.py", line 60, in _get_user_session_key
    return get_user_model()._meta.pk.to_python(request.session[SESSION_KEY])
                                               ~~~~~~~~~~~~~~~^^^^^^^^^^^^^
  File "C:\Users\Admin\AppData\Local\Programs\Python\Python311\Lib\site-packages\django\contrib\sessions\backends\base.py", line 53, in __getitem__
    return self._session[key]
           ^^^^^^^^^^^^^
  File "C:\Users\Admin\AppData\Local\Programs\Python\Python311\Lib\site-packages\django\contrib\sessions\backends\base.py", line 192, in _get_session
    self._session_cache = self.load()
                          ^^^^^^^^^^^
  File "C:\Users\Admin\AppData\Local\Programs\Python\Python311\Lib\site-packages\django\contrib\sessions\backends\db.py", line 42, in load
    s = self._get_session_from_db()
        ^^^^^^^^^^^^^^^^^^^^^^^^^^^
  File "C:\Users\Admin\AppData\Local\Programs\Python\Python311\Lib\site-packages\django\contrib\sessions\backends\db.py", line 32, in _get_session_from_db
    return self.model.objects.get(
           ^^^^^^^^^^^^^^^^^^^^^^^
  File "C:\Users\Admin\AppData\Local\Programs\Python\Python311\Lib\site-packages\django\db\models\manager.py", line 87, in manager_method
    return getattr(self.get_queryset(), name)(*args, **kwargs)
           ^^^^^^^^^^^^^^^^^^^^^^^^^^^^^^^^^^^^^^^^^^^^^^^^^^^
  File "C:\Users\Admin\AppData\Local\Programs\Python\Python311\Lib\site-packages\django\db\models\query.py", line 633, in get
    num = len(clone)
          ^^^^^^^^^^
  File "C:\Users\Admin\AppData\Local\Programs\Python\Python311\Lib\site-packages\django\db\models\query.py", line 380, in __len__
    self._fetch_all()
  File "C:\Users\Admin\AppData\Local\Programs\Python\Python311\Lib\site-packages\django\db\models\query.py", line 1881, in _fetch_all
    self._result_cache = list(self._iterable_class(self))
                         ^^^^^^^^^^^^^^^^^^^^^^^^^^^^^^^^
  File "C:\Users\Admin\AppData\Local\Programs\Python\Python311\Lib\site-packages\django\db\models\query.py", line 91, in __iter__
    results = compiler.execute_sql(
              ^^^^^^^^^^^^^^^^^^^^^
  File "C:\Users\Admin\AppData\Local\Programs\Python\Python311\Lib\site-packages\django\db\models\sql\compiler.py", line 1562, in execute_sql
    cursor.execute(sql, params)
  File "C:\Users\Admin\AppData\Local\Programs\Python\Python311\Lib\site-packages\django\db\backends\utils.py", line 102, in execute
    return super().execute(sql, params)
           ^^^^^^^^^^^^^^^^^^^^^^^^^^^^
  File "C:\Users\Admin\AppData\Local\Programs\Python\Python311\Lib\site-packages\django\db\backends\utils.py", line 67, in execute
    return self._execute_with_wrappers(
           ^^^^^^^^^^^^^^^^^^^^^^^^^^^^
  File "C:\Users\Admin\AppData\Local\Programs\Python\Python311\Lib\site-packages\django\db\backends\utils.py", line 80, in _execute_with_wrappers
    return executor(sql, params, many, context)
           ^^^^^^^^^^^^^^^^^^^^^^^^^^^^^^^^^^^^
  File "C:\Users\Admin\AppData\Local\Programs\Python\Python311\Lib\site-packages\django\db\backends\utils.py", line 84, in _execute
    with self.db.wrap_database_errors:
  File "C:\Users\Admin\AppData\Local\Programs\Python\Python311\Lib\site-packages\django\db\utils.py", line 91, in __exit__
    raise dj_exc_value.with_traceback(traceback) from exc_value
  File "C:\Users\Admin\AppData\Local\Programs\Python\Python311\Lib\site-packages\django\db\backends\utils.py", line 89, in _execute
    return self.cursor.execute(sql, params)
           ^^^^^^^^^^^^^^^^^^^^^^^^^^^^^^^^
  File "C:\Users\Admin\AppData\Local\Programs\Python\Python311\Lib\site-packages\django\db\backends\mysql\base.py", line 75, in execute
    return self.cursor.execute(query, args)
           ^^^^^^^^^^^^^^^^^^^^^^^^^^^^^^^^
  File "C:\Users\Admin\AppData\Local\Programs\Python\Python311\Lib\site-packages\MySQLdb\cursors.py", line 206, in execute
    res = self._query(query)
          ^^^^^^^^^^^^^^^^^^
  File "C:\Users\Admin\AppData\Local\Programs\Python\Python311\Lib\site-packages\MySQLdb\cursors.py", line 319, in _query
    db.query(q)
  File "C:\Users\Admin\AppData\Local\Programs\Python\Python311\Lib\site-packages\MySQLdb\connections.py", line 254, in query
    _mysql.connection.query(self, query)
django.db.utils.ProgrammingError: (1146, "Table 'logging.django_session' doesn't exist")
ERROR 2023-10-19 16:05:07,554 basehttp "GET /v1/ HTTP/1.1" 500 250033
WARNING 2023-10-19 16:05:32,796 log Not Found: /
WARNING 2023-10-19 16:05:32,802 basehttp "GET / HTTP/1.1" 404 2163
ERROR 2023-10-19 16:05:38,676 log Internal Server Error: /v1/
Traceback (most recent call last):
  File "C:\Users\Admin\AppData\Local\Programs\Python\Python311\Lib\site-packages\django\contrib\sessions\backends\base.py", line 187, in _get_session
    return self._session_cache
           ^^^^^^^^^^^^^^^^^^^
AttributeError: 'SessionStore' object has no attribute '_session_cache'

During handling of the above exception, another exception occurred:

Traceback (most recent call last):
  File "C:\Users\Admin\AppData\Local\Programs\Python\Python311\Lib\site-packages\django\db\backends\utils.py", line 89, in _execute
    return self.cursor.execute(sql, params)
           ^^^^^^^^^^^^^^^^^^^^^^^^^^^^^^^^
  File "C:\Users\Admin\AppData\Local\Programs\Python\Python311\Lib\site-packages\django\db\backends\mysql\base.py", line 75, in execute
    return self.cursor.execute(query, args)
           ^^^^^^^^^^^^^^^^^^^^^^^^^^^^^^^^
  File "C:\Users\Admin\AppData\Local\Programs\Python\Python311\Lib\site-packages\MySQLdb\cursors.py", line 206, in execute
    res = self._query(query)
          ^^^^^^^^^^^^^^^^^^
  File "C:\Users\Admin\AppData\Local\Programs\Python\Python311\Lib\site-packages\MySQLdb\cursors.py", line 319, in _query
    db.query(q)
  File "C:\Users\Admin\AppData\Local\Programs\Python\Python311\Lib\site-packages\MySQLdb\connections.py", line 254, in query
    _mysql.connection.query(self, query)
MySQLdb.ProgrammingError: (1146, "Table 'logging.django_session' doesn't exist")

The above exception was the direct cause of the following exception:

Traceback (most recent call last):
  File "C:\Users\Admin\AppData\Local\Programs\Python\Python311\Lib\site-packages\django\core\handlers\exception.py", line 55, in inner
    response = get_response(request)
               ^^^^^^^^^^^^^^^^^^^^^
  File "C:\Users\Admin\AppData\Local\Programs\Python\Python311\Lib\site-packages\django\core\handlers\base.py", line 197, in _get_response
    response = wrapped_callback(request, *callback_args, **callback_kwargs)
               ^^^^^^^^^^^^^^^^^^^^^^^^^^^^^^^^^^^^^^^^^^^^^^^^^^^^^^^^^^^^
  File "C:\Users\Admin\AppData\Local\Programs\Python\Python311\Lib\site-packages\django\views\decorators\csrf.py", line 56, in wrapper_view
    return view_func(*args, **kwargs)
           ^^^^^^^^^^^^^^^^^^^^^^^^^^
  File "C:\Users\Admin\AppData\Local\Programs\Python\Python311\Lib\site-packages\django\views\generic\base.py", line 104, in view
    return self.dispatch(request, *args, **kwargs)
           ^^^^^^^^^^^^^^^^^^^^^^^^^^^^^^^^^^^^^^^
  File "C:\Users\Admin\AppData\Local\Programs\Python\Python311\Lib\site-packages\rest_framework\views.py", line 509, in dispatch
    response = self.handle_exception(exc)
               ^^^^^^^^^^^^^^^^^^^^^^^^^^
  File "C:\Users\Admin\AppData\Local\Programs\Python\Python311\Lib\site-packages\rest_framework\views.py", line 469, in handle_exception
    self.raise_uncaught_exception(exc)
  File "C:\Users\Admin\AppData\Local\Programs\Python\Python311\Lib\site-packages\rest_framework\views.py", line 480, in raise_uncaught_exception
    raise exc
  File "C:\Users\Admin\AppData\Local\Programs\Python\Python311\Lib\site-packages\rest_framework\views.py", line 497, in dispatch
    self.initial(request, *args, **kwargs)
  File "C:\Users\Admin\AppData\Local\Programs\Python\Python311\Lib\site-packages\rest_framework\views.py", line 414, in initial
    self.perform_authentication(request)
  File "C:\Users\Admin\AppData\Local\Programs\Python\Python311\Lib\site-packages\rest_framework\views.py", line 324, in perform_authentication
    request.user
  File "C:\Users\Admin\AppData\Local\Programs\Python\Python311\Lib\site-packages\rest_framework\request.py", line 227, in user
    self._authenticate()
  File "C:\Users\Admin\AppData\Local\Programs\Python\Python311\Lib\site-packages\rest_framework\request.py", line 380, in _authenticate
    user_auth_tuple = authenticator.authenticate(self)
                      ^^^^^^^^^^^^^^^^^^^^^^^^^^^^^^^^
  File "C:\Users\Admin\AppData\Local\Programs\Python\Python311\Lib\site-packages\rest_framework\authentication.py", line 127, in authenticate
    if not user or not user.is_active:
  File "C:\Users\Admin\AppData\Local\Programs\Python\Python311\Lib\site-packages\django\utils\functional.py", line 266, in inner
    self._setup()
  File "C:\Users\Admin\AppData\Local\Programs\Python\Python311\Lib\site-packages\django\utils\functional.py", line 419, in _setup
    self._wrapped = self._setupfunc()
                    ^^^^^^^^^^^^^^^^^
  File "C:\Users\Admin\AppData\Local\Programs\Python\Python311\Lib\site-packages\django\contrib\auth\middleware.py", line 25, in <lambda>
    request.user = SimpleLazyObject(lambda: get_user(request))
                                            ^^^^^^^^^^^^^^^^^
  File "C:\Users\Admin\AppData\Local\Programs\Python\Python311\Lib\site-packages\django\contrib\auth\middleware.py", line 11, in get_user
    request._cached_user = auth.get_user(request)
                           ^^^^^^^^^^^^^^^^^^^^^^
  File "C:\Users\Admin\AppData\Local\Programs\Python\Python311\Lib\site-packages\django\contrib\auth\__init__.py", line 191, in get_user
    user_id = _get_user_session_key(request)
              ^^^^^^^^^^^^^^^^^^^^^^^^^^^^^^
  File "C:\Users\Admin\AppData\Local\Programs\Python\Python311\Lib\site-packages\django\contrib\auth\__init__.py", line 60, in _get_user_session_key
    return get_user_model()._meta.pk.to_python(request.session[SESSION_KEY])
                                               ~~~~~~~~~~~~~~~^^^^^^^^^^^^^
  File "C:\Users\Admin\AppData\Local\Programs\Python\Python311\Lib\site-packages\django\contrib\sessions\backends\base.py", line 53, in __getitem__
    return self._session[key]
           ^^^^^^^^^^^^^
  File "C:\Users\Admin\AppData\Local\Programs\Python\Python311\Lib\site-packages\django\contrib\sessions\backends\base.py", line 192, in _get_session
    self._session_cache = self.load()
                          ^^^^^^^^^^^
  File "C:\Users\Admin\AppData\Local\Programs\Python\Python311\Lib\site-packages\django\contrib\sessions\backends\db.py", line 42, in load
    s = self._get_session_from_db()
        ^^^^^^^^^^^^^^^^^^^^^^^^^^^
  File "C:\Users\Admin\AppData\Local\Programs\Python\Python311\Lib\site-packages\django\contrib\sessions\backends\db.py", line 32, in _get_session_from_db
    return self.model.objects.get(
           ^^^^^^^^^^^^^^^^^^^^^^^
  File "C:\Users\Admin\AppData\Local\Programs\Python\Python311\Lib\site-packages\django\db\models\manager.py", line 87, in manager_method
    return getattr(self.get_queryset(), name)(*args, **kwargs)
           ^^^^^^^^^^^^^^^^^^^^^^^^^^^^^^^^^^^^^^^^^^^^^^^^^^^
  File "C:\Users\Admin\AppData\Local\Programs\Python\Python311\Lib\site-packages\django\db\models\query.py", line 633, in get
    num = len(clone)
          ^^^^^^^^^^
  File "C:\Users\Admin\AppData\Local\Programs\Python\Python311\Lib\site-packages\django\db\models\query.py", line 380, in __len__
    self._fetch_all()
  File "C:\Users\Admin\AppData\Local\Programs\Python\Python311\Lib\site-packages\django\db\models\query.py", line 1881, in _fetch_all
    self._result_cache = list(self._iterable_class(self))
                         ^^^^^^^^^^^^^^^^^^^^^^^^^^^^^^^^
  File "C:\Users\Admin\AppData\Local\Programs\Python\Python311\Lib\site-packages\django\db\models\query.py", line 91, in __iter__
    results = compiler.execute_sql(
              ^^^^^^^^^^^^^^^^^^^^^
  File "C:\Users\Admin\AppData\Local\Programs\Python\Python311\Lib\site-packages\django\db\models\sql\compiler.py", line 1562, in execute_sql
    cursor.execute(sql, params)
  File "C:\Users\Admin\AppData\Local\Programs\Python\Python311\Lib\site-packages\django\db\backends\utils.py", line 102, in execute
    return super().execute(sql, params)
           ^^^^^^^^^^^^^^^^^^^^^^^^^^^^
  File "C:\Users\Admin\AppData\Local\Programs\Python\Python311\Lib\site-packages\django\db\backends\utils.py", line 67, in execute
    return self._execute_with_wrappers(
           ^^^^^^^^^^^^^^^^^^^^^^^^^^^^
  File "C:\Users\Admin\AppData\Local\Programs\Python\Python311\Lib\site-packages\django\db\backends\utils.py", line 80, in _execute_with_wrappers
    return executor(sql, params, many, context)
           ^^^^^^^^^^^^^^^^^^^^^^^^^^^^^^^^^^^^
  File "C:\Users\Admin\AppData\Local\Programs\Python\Python311\Lib\site-packages\django\db\backends\utils.py", line 84, in _execute
    with self.db.wrap_database_errors:
  File "C:\Users\Admin\AppData\Local\Programs\Python\Python311\Lib\site-packages\django\db\utils.py", line 91, in __exit__
    raise dj_exc_value.with_traceback(traceback) from exc_value
  File "C:\Users\Admin\AppData\Local\Programs\Python\Python311\Lib\site-packages\django\db\backends\utils.py", line 89, in _execute
    return self.cursor.execute(sql, params)
           ^^^^^^^^^^^^^^^^^^^^^^^^^^^^^^^^
  File "C:\Users\Admin\AppData\Local\Programs\Python\Python311\Lib\site-packages\django\db\backends\mysql\base.py", line 75, in execute
    return self.cursor.execute(query, args)
           ^^^^^^^^^^^^^^^^^^^^^^^^^^^^^^^^
  File "C:\Users\Admin\AppData\Local\Programs\Python\Python311\Lib\site-packages\MySQLdb\cursors.py", line 206, in execute
    res = self._query(query)
          ^^^^^^^^^^^^^^^^^^
  File "C:\Users\Admin\AppData\Local\Programs\Python\Python311\Lib\site-packages\MySQLdb\cursors.py", line 319, in _query
    db.query(q)
  File "C:\Users\Admin\AppData\Local\Programs\Python\Python311\Lib\site-packages\MySQLdb\connections.py", line 254, in query
    _mysql.connection.query(self, query)
django.db.utils.ProgrammingError: (1146, "Table 'logging.django_session' doesn't exist")
ERROR 2023-10-19 16:05:38,725 basehttp "GET /v1/ HTTP/1.1" 500 250035
WARNING 2023-10-19 16:07:13,604 log Not Found: /
WARNING 2023-10-19 16:07:13,608 basehttp "GET / HTTP/1.1" 404 2163
WARNING 2023-10-19 16:10:00,705 log Not Found: /
WARNING 2023-10-19 16:10:00,718 basehttp "GET / HTTP/1.1" 404 2163
WARNING 2023-10-19 16:10:27,912 log Not Found: /
WARNING 2023-10-19 16:10:27,913 basehttp "GET / HTTP/1.1" 404 2163
WARNING 2023-10-19 16:10:28,142 log Not Found: /favicon.ico
WARNING 2023-10-19 16:10:28,142 basehttp "GET /favicon.ico HTTP/1.1" 404 2214
WARNING 2023-10-19 16:11:56,015 log Method Not Allowed: /v1/student/
WARNING 2023-10-19 16:11:56,015 basehttp "PUT /v1/student/ HTTP/1.1" 405 40
WARNING 2023-10-19 16:12:02,899 log Method Not Allowed: /v1/student/
WARNING 2023-10-19 16:12:02,899 basehttp "PATCH /v1/student/ HTTP/1.1" 405 42
WARNING 2023-10-19 16:12:19,298 log Method Not Allowed: /v1/student/
WARNING 2023-10-19 16:12:19,298 basehttp "PUT /v1/student/ HTTP/1.1" 405 40
ERROR 2023-10-19 16:12:48,615 log Internal Server Error: /v1/student/1/
Traceback (most recent call last):
  File "C:\Users\Admin\AppData\Local\Programs\Python\Python311\Lib\site-packages\django\core\handlers\exception.py", line 55, in inner
    response = get_response(request)
               ^^^^^^^^^^^^^^^^^^^^^
  File "C:\Users\Admin\AppData\Local\Programs\Python\Python311\Lib\site-packages\django\core\handlers\base.py", line 197, in _get_response
    response = wrapped_callback(request, *callback_args, **callback_kwargs)
               ^^^^^^^^^^^^^^^^^^^^^^^^^^^^^^^^^^^^^^^^^^^^^^^^^^^^^^^^^^^^
  File "C:\Users\Admin\AppData\Local\Programs\Python\Python311\Lib\site-packages\django\views\decorators\csrf.py", line 56, in wrapper_view
    return view_func(*args, **kwargs)
           ^^^^^^^^^^^^^^^^^^^^^^^^^^
  File "C:\Users\Admin\AppData\Local\Programs\Python\Python311\Lib\site-packages\rest_framework\viewsets.py", line 125, in view
    return self.dispatch(request, *args, **kwargs)
           ^^^^^^^^^^^^^^^^^^^^^^^^^^^^^^^^^^^^^^^
  File "C:\Users\Admin\AppData\Local\Programs\Python\Python311\Lib\site-packages\rest_framework\views.py", line 509, in dispatch
    response = self.handle_exception(exc)
               ^^^^^^^^^^^^^^^^^^^^^^^^^^
  File "C:\Users\Admin\AppData\Local\Programs\Python\Python311\Lib\site-packages\rest_framework\views.py", line 469, in handle_exception
    self.raise_uncaught_exception(exc)
  File "C:\Users\Admin\AppData\Local\Programs\Python\Python311\Lib\site-packages\rest_framework\views.py", line 480, in raise_uncaught_exception
    raise exc
  File "C:\Users\Admin\AppData\Local\Programs\Python\Python311\Lib\site-packages\rest_framework\views.py", line 506, in dispatch
    response = handler(request, *args, **kwargs)
               ^^^^^^^^^^^^^^^^^^^^^^^^^^^^^^^^^
  File "D:\drf\project task\log crud task 4\backend\app1\views.py", line 38, in update
    post=get_list_or_404(post,pk=pk)
                         ^^^^
UnboundLocalError: cannot access local variable 'post' where it is not associated with a value
ERROR 2023-10-19 16:12:48,622 basehttp "PUT /v1/student/1/ HTTP/1.1" 500 93548
WARNING 2023-10-19 16:13:03,385 log Method Not Allowed: /v1/student/1/
WARNING 2023-10-19 16:13:03,385 basehttp "GET /v1/student/1/ HTTP/1.1" 405 40
WARNING 2023-10-19 16:14:57,595 log Method Not Allowed: /v1/student/1/
WARNING 2023-10-19 16:14:57,595 basehttp "GET /v1/student/1/ HTTP/1.1" 405 40
ERROR 2023-10-19 16:15:10,593 log Internal Server Error: /v1/student/1/
Traceback (most recent call last):
  File "C:\Users\Admin\AppData\Local\Programs\Python\Python311\Lib\site-packages\django\core\handlers\exception.py", line 55, in inner
    response = get_response(request)
               ^^^^^^^^^^^^^^^^^^^^^
  File "C:\Users\Admin\AppData\Local\Programs\Python\Python311\Lib\site-packages\django\core\handlers\base.py", line 197, in _get_response
    response = wrapped_callback(request, *callback_args, **callback_kwargs)
               ^^^^^^^^^^^^^^^^^^^^^^^^^^^^^^^^^^^^^^^^^^^^^^^^^^^^^^^^^^^^
  File "C:\Users\Admin\AppData\Local\Programs\Python\Python311\Lib\site-packages\django\views\decorators\csrf.py", line 56, in wrapper_view
    return view_func(*args, **kwargs)
           ^^^^^^^^^^^^^^^^^^^^^^^^^^
  File "C:\Users\Admin\AppData\Local\Programs\Python\Python311\Lib\site-packages\rest_framework\viewsets.py", line 125, in view
    return self.dispatch(request, *args, **kwargs)
           ^^^^^^^^^^^^^^^^^^^^^^^^^^^^^^^^^^^^^^^
  File "C:\Users\Admin\AppData\Local\Programs\Python\Python311\Lib\site-packages\rest_framework\views.py", line 509, in dispatch
    response = self.handle_exception(exc)
               ^^^^^^^^^^^^^^^^^^^^^^^^^^
  File "C:\Users\Admin\AppData\Local\Programs\Python\Python311\Lib\site-packages\rest_framework\views.py", line 469, in handle_exception
    self.raise_uncaught_exception(exc)
  File "C:\Users\Admin\AppData\Local\Programs\Python\Python311\Lib\site-packages\rest_framework\views.py", line 480, in raise_uncaught_exception
    raise exc
  File "C:\Users\Admin\AppData\Local\Programs\Python\Python311\Lib\site-packages\rest_framework\views.py", line 506, in dispatch
    response = handler(request, *args, **kwargs)
               ^^^^^^^^^^^^^^^^^^^^^^^^^^^^^^^^^
  File "D:\drf\project task\log crud task 4\backend\app1\views.py", line 38, in update
    post=get_list_or_404(post,pk=pk)
                         ^^^^
UnboundLocalError: cannot access local variable 'post' where it is not associated with a value
ERROR 2023-10-19 16:15:10,601 basehttp "PUT /v1/student/1/ HTTP/1.1" 500 93548
ERROR 2023-10-19 16:19:47,998 log Internal Server Error: /v1/student/1/
Traceback (most recent call last):
  File "C:\Users\Admin\AppData\Local\Programs\Python\Python311\Lib\site-packages\rest_framework\fields.py", line 446, in get_attribute
    return get_attribute(instance, self.source_attrs)
           ^^^^^^^^^^^^^^^^^^^^^^^^^^^^^^^^^^^^^^^^^^
  File "C:\Users\Admin\AppData\Local\Programs\Python\Python311\Lib\site-packages\rest_framework\fields.py", line 96, in get_attribute
    instance = getattr(instance, attr)
               ^^^^^^^^^^^^^^^^^^^^^^^
AttributeError: 'list' object has no attribute 'fname'

During handling of the above exception, another exception occurred:

Traceback (most recent call last):
  File "C:\Users\Admin\AppData\Local\Programs\Python\Python311\Lib\site-packages\django\core\handlers\exception.py", line 55, in inner
    response = get_response(request)
               ^^^^^^^^^^^^^^^^^^^^^
  File "C:\Users\Admin\AppData\Local\Programs\Python\Python311\Lib\site-packages\django\core\handlers\base.py", line 197, in _get_response
    response = wrapped_callback(request, *callback_args, **callback_kwargs)
               ^^^^^^^^^^^^^^^^^^^^^^^^^^^^^^^^^^^^^^^^^^^^^^^^^^^^^^^^^^^^
  File "C:\Users\Admin\AppData\Local\Programs\Python\Python311\Lib\site-packages\django\views\decorators\csrf.py", line 56, in wrapper_view
    return view_func(*args, **kwargs)
           ^^^^^^^^^^^^^^^^^^^^^^^^^^
  File "C:\Users\Admin\AppData\Local\Programs\Python\Python311\Lib\site-packages\rest_framework\viewsets.py", line 125, in view
    return self.dispatch(request, *args, **kwargs)
           ^^^^^^^^^^^^^^^^^^^^^^^^^^^^^^^^^^^^^^^
  File "C:\Users\Admin\AppData\Local\Programs\Python\Python311\Lib\site-packages\rest_framework\views.py", line 509, in dispatch
    response = self.handle_exception(exc)
               ^^^^^^^^^^^^^^^^^^^^^^^^^^
  File "C:\Users\Admin\AppData\Local\Programs\Python\Python311\Lib\site-packages\rest_framework\views.py", line 469, in handle_exception
    self.raise_uncaught_exception(exc)
  File "C:\Users\Admin\AppData\Local\Programs\Python\Python311\Lib\site-packages\rest_framework\views.py", line 480, in raise_uncaught_exception
    raise exc
  File "C:\Users\Admin\AppData\Local\Programs\Python\Python311\Lib\site-packages\rest_framework\views.py", line 506, in dispatch
    response = handler(request, *args, **kwargs)
               ^^^^^^^^^^^^^^^^^^^^^^^^^^^^^^^^^
  File "D:\drf\project task\log crud task 4\backend\app1\views.py", line 42, in update
    return Response(data=serializer.data,status=status.HTTP_205_RESET_CONTENT)
                         ^^^^^^^^^^^^^^^
  File "C:\Users\Admin\AppData\Local\Programs\Python\Python311\Lib\site-packages\rest_framework\serializers.py", line 555, in data
    ret = super().data
          ^^^^^^^^^^^^
  File "C:\Users\Admin\AppData\Local\Programs\Python\Python311\Lib\site-packages\rest_framework\serializers.py", line 253, in data
    self._data = self.to_representation(self.instance)
                 ^^^^^^^^^^^^^^^^^^^^^^^^^^^^^^^^^^^^^
  File "C:\Users\Admin\AppData\Local\Programs\Python\Python311\Lib\site-packages\rest_framework\serializers.py", line 509, in to_representation
    attribute = field.get_attribute(instance)
                ^^^^^^^^^^^^^^^^^^^^^^^^^^^^^
  File "C:\Users\Admin\AppData\Local\Programs\Python\Python311\Lib\site-packages\rest_framework\fields.py", line 479, in get_attribute
    raise type(exc)(msg)
AttributeError: Got AttributeError when attempting to get a value for field `fname` on serializer `StudentSerializer`.
The serializer field might be named incorrectly and not match any attribute or key on the `list` instance.
Original exception text was: 'list' object has no attribute 'fname'.
ERROR 2023-10-19 16:19:48,028 basehttp "PUT /v1/student/1/ HTTP/1.1" 500 124956
ERROR 2023-10-19 16:20:56,853 log Internal Server Error: /v1/student/1/
Traceback (most recent call last):
  File "C:\Users\Admin\AppData\Local\Programs\Python\Python311\Lib\site-packages\rest_framework\fields.py", line 446, in get_attribute
    return get_attribute(instance, self.source_attrs)
           ^^^^^^^^^^^^^^^^^^^^^^^^^^^^^^^^^^^^^^^^^^
  File "C:\Users\Admin\AppData\Local\Programs\Python\Python311\Lib\site-packages\rest_framework\fields.py", line 96, in get_attribute
    instance = getattr(instance, attr)
               ^^^^^^^^^^^^^^^^^^^^^^^
AttributeError: 'list' object has no attribute 'fname'

During handling of the above exception, another exception occurred:

Traceback (most recent call last):
  File "C:\Users\Admin\AppData\Local\Programs\Python\Python311\Lib\site-packages\django\core\handlers\exception.py", line 55, in inner
    response = get_response(request)
               ^^^^^^^^^^^^^^^^^^^^^
  File "C:\Users\Admin\AppData\Local\Programs\Python\Python311\Lib\site-packages\django\core\handlers\base.py", line 197, in _get_response
    response = wrapped_callback(request, *callback_args, **callback_kwargs)
               ^^^^^^^^^^^^^^^^^^^^^^^^^^^^^^^^^^^^^^^^^^^^^^^^^^^^^^^^^^^^
  File "C:\Users\Admin\AppData\Local\Programs\Python\Python311\Lib\site-packages\django\views\decorators\csrf.py", line 56, in wrapper_view
    return view_func(*args, **kwargs)
           ^^^^^^^^^^^^^^^^^^^^^^^^^^
  File "C:\Users\Admin\AppData\Local\Programs\Python\Python311\Lib\site-packages\rest_framework\viewsets.py", line 125, in view
    return self.dispatch(request, *args, **kwargs)
           ^^^^^^^^^^^^^^^^^^^^^^^^^^^^^^^^^^^^^^^
  File "C:\Users\Admin\AppData\Local\Programs\Python\Python311\Lib\site-packages\rest_framework\views.py", line 509, in dispatch
    response = self.handle_exception(exc)
               ^^^^^^^^^^^^^^^^^^^^^^^^^^
  File "C:\Users\Admin\AppData\Local\Programs\Python\Python311\Lib\site-packages\rest_framework\views.py", line 469, in handle_exception
    self.raise_uncaught_exception(exc)
  File "C:\Users\Admin\AppData\Local\Programs\Python\Python311\Lib\site-packages\rest_framework\views.py", line 480, in raise_uncaught_exception
    raise exc
  File "C:\Users\Admin\AppData\Local\Programs\Python\Python311\Lib\site-packages\rest_framework\views.py", line 506, in dispatch
    response = handler(request, *args, **kwargs)
               ^^^^^^^^^^^^^^^^^^^^^^^^^^^^^^^^^
  File "D:\drf\project task\log crud task 4\backend\app1\views.py", line 49, in partial_update
    return Response(data=serializer.data,status=status.HTTP_205_RESET_CONTENT)
                         ^^^^^^^^^^^^^^^
  File "C:\Users\Admin\AppData\Local\Programs\Python\Python311\Lib\site-packages\rest_framework\serializers.py", line 555, in data
    ret = super().data
          ^^^^^^^^^^^^
  File "C:\Users\Admin\AppData\Local\Programs\Python\Python311\Lib\site-packages\rest_framework\serializers.py", line 253, in data
    self._data = self.to_representation(self.instance)
                 ^^^^^^^^^^^^^^^^^^^^^^^^^^^^^^^^^^^^^
  File "C:\Users\Admin\AppData\Local\Programs\Python\Python311\Lib\site-packages\rest_framework\serializers.py", line 509, in to_representation
    attribute = field.get_attribute(instance)
                ^^^^^^^^^^^^^^^^^^^^^^^^^^^^^
  File "C:\Users\Admin\AppData\Local\Programs\Python\Python311\Lib\site-packages\rest_framework\fields.py", line 479, in get_attribute
    raise type(exc)(msg)
AttributeError: Got AttributeError when attempting to get a value for field `fname` on serializer `StudentSerializer`.
The serializer field might be named incorrectly and not match any attribute or key on the `list` instance.
Original exception text was: 'list' object has no attribute 'fname'.
ERROR 2023-10-19 16:20:56,887 basehttp "PATCH /v1/student/1/ HTTP/1.1" 500 125111
ERROR 2023-10-19 16:21:32,103 log Internal Server Error: /v1/student/1/
Traceback (most recent call last):
  File "C:\Users\Admin\AppData\Local\Programs\Python\Python311\Lib\site-packages\rest_framework\fields.py", line 446, in get_attribute
    return get_attribute(instance, self.source_attrs)
           ^^^^^^^^^^^^^^^^^^^^^^^^^^^^^^^^^^^^^^^^^^
  File "C:\Users\Admin\AppData\Local\Programs\Python\Python311\Lib\site-packages\rest_framework\fields.py", line 96, in get_attribute
    instance = getattr(instance, attr)
               ^^^^^^^^^^^^^^^^^^^^^^^
AttributeError: 'list' object has no attribute 'fname'

During handling of the above exception, another exception occurred:

Traceback (most recent call last):
  File "C:\Users\Admin\AppData\Local\Programs\Python\Python311\Lib\site-packages\django\core\handlers\exception.py", line 55, in inner
    response = get_response(request)
               ^^^^^^^^^^^^^^^^^^^^^
  File "C:\Users\Admin\AppData\Local\Programs\Python\Python311\Lib\site-packages\django\core\handlers\base.py", line 197, in _get_response
    response = wrapped_callback(request, *callback_args, **callback_kwargs)
               ^^^^^^^^^^^^^^^^^^^^^^^^^^^^^^^^^^^^^^^^^^^^^^^^^^^^^^^^^^^^
  File "C:\Users\Admin\AppData\Local\Programs\Python\Python311\Lib\site-packages\django\views\decorators\csrf.py", line 56, in wrapper_view
    return view_func(*args, **kwargs)
           ^^^^^^^^^^^^^^^^^^^^^^^^^^
  File "C:\Users\Admin\AppData\Local\Programs\Python\Python311\Lib\site-packages\rest_framework\viewsets.py", line 125, in view
    return self.dispatch(request, *args, **kwargs)
           ^^^^^^^^^^^^^^^^^^^^^^^^^^^^^^^^^^^^^^^
  File "C:\Users\Admin\AppData\Local\Programs\Python\Python311\Lib\site-packages\rest_framework\views.py", line 509, in dispatch
    response = self.handle_exception(exc)
               ^^^^^^^^^^^^^^^^^^^^^^^^^^
  File "C:\Users\Admin\AppData\Local\Programs\Python\Python311\Lib\site-packages\rest_framework\views.py", line 469, in handle_exception
    self.raise_uncaught_exception(exc)
  File "C:\Users\Admin\AppData\Local\Programs\Python\Python311\Lib\site-packages\rest_framework\views.py", line 480, in raise_uncaught_exception
    raise exc
  File "C:\Users\Admin\AppData\Local\Programs\Python\Python311\Lib\site-packages\rest_framework\views.py", line 506, in dispatch
    response = handler(request, *args, **kwargs)
               ^^^^^^^^^^^^^^^^^^^^^^^^^^^^^^^^^
  File "D:\drf\project task\log crud task 4\backend\app1\views.py", line 49, in partial_update
    return Response(data=serializer.data,status=status.HTTP_205_RESET_CONTENT)
                         ^^^^^^^^^^^^^^^
  File "C:\Users\Admin\AppData\Local\Programs\Python\Python311\Lib\site-packages\rest_framework\serializers.py", line 555, in data
    ret = super().data
          ^^^^^^^^^^^^
  File "C:\Users\Admin\AppData\Local\Programs\Python\Python311\Lib\site-packages\rest_framework\serializers.py", line 253, in data
    self._data = self.to_representation(self.instance)
                 ^^^^^^^^^^^^^^^^^^^^^^^^^^^^^^^^^^^^^
  File "C:\Users\Admin\AppData\Local\Programs\Python\Python311\Lib\site-packages\rest_framework\serializers.py", line 509, in to_representation
    attribute = field.get_attribute(instance)
                ^^^^^^^^^^^^^^^^^^^^^^^^^^^^^
  File "C:\Users\Admin\AppData\Local\Programs\Python\Python311\Lib\site-packages\rest_framework\fields.py", line 479, in get_attribute
    raise type(exc)(msg)
AttributeError: Got AttributeError when attempting to get a value for field `fname` on serializer `StudentSerializer`.
The serializer field might be named incorrectly and not match any attribute or key on the `list` instance.
Original exception text was: 'list' object has no attribute 'fname'.
ERROR 2023-10-19 16:21:32,124 basehttp "PATCH /v1/student/1/ HTTP/1.1" 500 125131
ERROR 2023-10-19 16:21:56,884 log Internal Server Error: /v1/student/1/
Traceback (most recent call last):
  File "C:\Users\Admin\AppData\Local\Programs\Python\Python311\Lib\site-packages\rest_framework\fields.py", line 446, in get_attribute
    return get_attribute(instance, self.source_attrs)
           ^^^^^^^^^^^^^^^^^^^^^^^^^^^^^^^^^^^^^^^^^^
  File "C:\Users\Admin\AppData\Local\Programs\Python\Python311\Lib\site-packages\rest_framework\fields.py", line 96, in get_attribute
    instance = getattr(instance, attr)
               ^^^^^^^^^^^^^^^^^^^^^^^
AttributeError: 'list' object has no attribute 'fname'

During handling of the above exception, another exception occurred:

Traceback (most recent call last):
  File "C:\Users\Admin\AppData\Local\Programs\Python\Python311\Lib\site-packages\django\core\handlers\exception.py", line 55, in inner
    response = get_response(request)
               ^^^^^^^^^^^^^^^^^^^^^
  File "C:\Users\Admin\AppData\Local\Programs\Python\Python311\Lib\site-packages\django\core\handlers\base.py", line 197, in _get_response
    response = wrapped_callback(request, *callback_args, **callback_kwargs)
               ^^^^^^^^^^^^^^^^^^^^^^^^^^^^^^^^^^^^^^^^^^^^^^^^^^^^^^^^^^^^
  File "C:\Users\Admin\AppData\Local\Programs\Python\Python311\Lib\site-packages\django\views\decorators\csrf.py", line 56, in wrapper_view
    return view_func(*args, **kwargs)
           ^^^^^^^^^^^^^^^^^^^^^^^^^^
  File "C:\Users\Admin\AppData\Local\Programs\Python\Python311\Lib\site-packages\rest_framework\viewsets.py", line 125, in view
    return self.dispatch(request, *args, **kwargs)
           ^^^^^^^^^^^^^^^^^^^^^^^^^^^^^^^^^^^^^^^
  File "C:\Users\Admin\AppData\Local\Programs\Python\Python311\Lib\site-packages\rest_framework\views.py", line 509, in dispatch
    response = self.handle_exception(exc)
               ^^^^^^^^^^^^^^^^^^^^^^^^^^
  File "C:\Users\Admin\AppData\Local\Programs\Python\Python311\Lib\site-packages\rest_framework\views.py", line 469, in handle_exception
    self.raise_uncaught_exception(exc)
  File "C:\Users\Admin\AppData\Local\Programs\Python\Python311\Lib\site-packages\rest_framework\views.py", line 480, in raise_uncaught_exception
    raise exc
  File "C:\Users\Admin\AppData\Local\Programs\Python\Python311\Lib\site-packages\rest_framework\views.py", line 506, in dispatch
    response = handler(request, *args, **kwargs)
               ^^^^^^^^^^^^^^^^^^^^^^^^^^^^^^^^^
  File "D:\drf\project task\log crud task 4\backend\app1\views.py", line 49, in partial_update
    return Response(data=serializer.data,status=status.HTTP_205_RESET_CONTENT)
                         ^^^^^^^^^^^^^^^
  File "C:\Users\Admin\AppData\Local\Programs\Python\Python311\Lib\site-packages\rest_framework\serializers.py", line 555, in data
    ret = super().data
          ^^^^^^^^^^^^
  File "C:\Users\Admin\AppData\Local\Programs\Python\Python311\Lib\site-packages\rest_framework\serializers.py", line 253, in data
    self._data = self.to_representation(self.instance)
                 ^^^^^^^^^^^^^^^^^^^^^^^^^^^^^^^^^^^^^
  File "C:\Users\Admin\AppData\Local\Programs\Python\Python311\Lib\site-packages\rest_framework\serializers.py", line 509, in to_representation
    attribute = field.get_attribute(instance)
                ^^^^^^^^^^^^^^^^^^^^^^^^^^^^^
  File "C:\Users\Admin\AppData\Local\Programs\Python\Python311\Lib\site-packages\rest_framework\fields.py", line 479, in get_attribute
    raise type(exc)(msg)
AttributeError: Got AttributeError when attempting to get a value for field `fname` on serializer `StudentSerializer`.
The serializer field might be named incorrectly and not match any attribute or key on the `list` instance.
Original exception text was: 'list' object has no attribute 'fname'.
ERROR 2023-10-19 16:21:56,906 basehttp "PATCH /v1/student/1/ HTTP/1.1" 500 125131
ERROR 2023-10-19 16:24:49,338 log Internal Server Error: /v1/student/1/
Traceback (most recent call last):
  File "C:\Users\Admin\AppData\Local\Programs\Python\Python311\Lib\site-packages\rest_framework\fields.py", line 446, in get_attribute
    return get_attribute(instance, self.source_attrs)
           ^^^^^^^^^^^^^^^^^^^^^^^^^^^^^^^^^^^^^^^^^^
  File "C:\Users\Admin\AppData\Local\Programs\Python\Python311\Lib\site-packages\rest_framework\fields.py", line 96, in get_attribute
    instance = getattr(instance, attr)
               ^^^^^^^^^^^^^^^^^^^^^^^
AttributeError: 'list' object has no attribute 'fname'

During handling of the above exception, another exception occurred:

Traceback (most recent call last):
  File "C:\Users\Admin\AppData\Local\Programs\Python\Python311\Lib\site-packages\django\core\handlers\exception.py", line 55, in inner
    response = get_response(request)
               ^^^^^^^^^^^^^^^^^^^^^
  File "C:\Users\Admin\AppData\Local\Programs\Python\Python311\Lib\site-packages\django\core\handlers\base.py", line 197, in _get_response
    response = wrapped_callback(request, *callback_args, **callback_kwargs)
               ^^^^^^^^^^^^^^^^^^^^^^^^^^^^^^^^^^^^^^^^^^^^^^^^^^^^^^^^^^^^
  File "C:\Users\Admin\AppData\Local\Programs\Python\Python311\Lib\site-packages\django\views\decorators\csrf.py", line 56, in wrapper_view
    return view_func(*args, **kwargs)
           ^^^^^^^^^^^^^^^^^^^^^^^^^^
  File "C:\Users\Admin\AppData\Local\Programs\Python\Python311\Lib\site-packages\rest_framework\viewsets.py", line 125, in view
    return self.dispatch(request, *args, **kwargs)
           ^^^^^^^^^^^^^^^^^^^^^^^^^^^^^^^^^^^^^^^
  File "C:\Users\Admin\AppData\Local\Programs\Python\Python311\Lib\site-packages\rest_framework\views.py", line 509, in dispatch
    response = self.handle_exception(exc)
               ^^^^^^^^^^^^^^^^^^^^^^^^^^
  File "C:\Users\Admin\AppData\Local\Programs\Python\Python311\Lib\site-packages\rest_framework\views.py", line 469, in handle_exception
    self.raise_uncaught_exception(exc)
  File "C:\Users\Admin\AppData\Local\Programs\Python\Python311\Lib\site-packages\rest_framework\views.py", line 480, in raise_uncaught_exception
    raise exc
  File "C:\Users\Admin\AppData\Local\Programs\Python\Python311\Lib\site-packages\rest_framework\views.py", line 506, in dispatch
    response = handler(request, *args, **kwargs)
               ^^^^^^^^^^^^^^^^^^^^^^^^^^^^^^^^^
  File "D:\drf\project task\log crud task 4\backend\app1\views.py", line 42, in update
    return Response(data=serializer.data,status=status.HTTP_205_RESET_CONTENT)
                         ^^^^^^^^^^^^^^^
  File "C:\Users\Admin\AppData\Local\Programs\Python\Python311\Lib\site-packages\rest_framework\serializers.py", line 555, in data
    ret = super().data
          ^^^^^^^^^^^^
  File "C:\Users\Admin\AppData\Local\Programs\Python\Python311\Lib\site-packages\rest_framework\serializers.py", line 253, in data
    self._data = self.to_representation(self.instance)
                 ^^^^^^^^^^^^^^^^^^^^^^^^^^^^^^^^^^^^^
  File "C:\Users\Admin\AppData\Local\Programs\Python\Python311\Lib\site-packages\rest_framework\serializers.py", line 509, in to_representation
    attribute = field.get_attribute(instance)
                ^^^^^^^^^^^^^^^^^^^^^^^^^^^^^
  File "C:\Users\Admin\AppData\Local\Programs\Python\Python311\Lib\site-packages\rest_framework\fields.py", line 479, in get_attribute
    raise type(exc)(msg)
AttributeError: Got AttributeError when attempting to get a value for field `fname` on serializer `StudentSerializer`.
The serializer field might be named incorrectly and not match any attribute or key on the `list` instance.
Original exception text was: 'list' object has no attribute 'fname'.
ERROR 2023-10-19 16:24:49,353 basehttp "PUT /v1/student/1/ HTTP/1.1" 500 124976
WARNING 2023-10-19 16:27:30,207 log Method Not Allowed: /v1/student/1/
WARNING 2023-10-19 16:27:30,209 basehttp "GET /v1/student/1/ HTTP/1.1" 405 40
WARNING 2023-10-19 16:50:54,152 log Not Found: /
WARNING 2023-10-19 16:50:54,152 basehttp "GET / HTTP/1.1" 404 2163
WARNING 2023-10-19 17:57:19,008 log Bad Request: /v1/student/
WARNING 2023-10-19 17:57:19,009 basehttp "POST /v1/student/ HTTP/1.1" 400 73
WARNING 2023-10-19 17:58:42,193 log Bad Request: /v1/student/
WARNING 2023-10-19 17:58:42,193 basehttp "POST /v1/student/ HTTP/1.1" 400 38
WARNING 2023-10-19 17:59:08,058 log Bad Request: /v1/student/
WARNING 2023-10-19 17:59:08,058 basehttp "POST /v1/student/ HTTP/1.1" 400 38
WARNING 2023-10-19 18:00:33,574 log Bad Request: /v1/student/
WARNING 2023-10-19 18:00:33,579 basehttp "POST /v1/student/ HTTP/1.1" 400 38
WARNING 2023-10-19 18:02:10,052 log Bad Request: /v1/student/
WARNING 2023-10-19 18:02:10,052 basehttp "POST /v1/student/ HTTP/1.1" 400 38
WARNING 2023-10-19 18:08:02,319 log Bad Request: /v1/student/
WARNING 2023-10-19 18:08:02,324 basehttp "POST /v1/student/ HTTP/1.1" 400 38
ERROR 2023-10-19 18:08:32,238 log Internal Server Error: /v1/student/
Traceback (most recent call last):
  File "C:\Users\Admin\AppData\Local\Programs\Python\Python311\Lib\site-packages\django\db\backends\mysql\base.py", line 75, in execute
    return self.cursor.execute(query, args)
           ^^^^^^^^^^^^^^^^^^^^^^^^^^^^^^^^
  File "C:\Users\Admin\AppData\Local\Programs\Python\Python311\Lib\site-packages\MySQLdb\cursors.py", line 206, in execute
    res = self._query(query)
          ^^^^^^^^^^^^^^^^^^
  File "C:\Users\Admin\AppData\Local\Programs\Python\Python311\Lib\site-packages\MySQLdb\cursors.py", line 319, in _query
    db.query(q)
  File "C:\Users\Admin\AppData\Local\Programs\Python\Python311\Lib\site-packages\MySQLdb\connections.py", line 254, in query
    _mysql.connection.query(self, query)
MySQLdb.OperationalError: (1048, "Column 'gender' cannot be null")

During handling of the above exception, another exception occurred:

Traceback (most recent call last):
  File "C:\Users\Admin\AppData\Local\Programs\Python\Python311\Lib\site-packages\django\core\handlers\exception.py", line 55, in inner
    response = get_response(request)
               ^^^^^^^^^^^^^^^^^^^^^
  File "C:\Users\Admin\AppData\Local\Programs\Python\Python311\Lib\site-packages\django\core\handlers\base.py", line 197, in _get_response
    response = wrapped_callback(request, *callback_args, **callback_kwargs)
               ^^^^^^^^^^^^^^^^^^^^^^^^^^^^^^^^^^^^^^^^^^^^^^^^^^^^^^^^^^^^
  File "C:\Users\Admin\AppData\Local\Programs\Python\Python311\Lib\site-packages\django\views\decorators\csrf.py", line 56, in wrapper_view
    return view_func(*args, **kwargs)
           ^^^^^^^^^^^^^^^^^^^^^^^^^^
  File "C:\Users\Admin\AppData\Local\Programs\Python\Python311\Lib\site-packages\rest_framework\viewsets.py", line 125, in view
    return self.dispatch(request, *args, **kwargs)
           ^^^^^^^^^^^^^^^^^^^^^^^^^^^^^^^^^^^^^^^
  File "C:\Users\Admin\AppData\Local\Programs\Python\Python311\Lib\site-packages\rest_framework\views.py", line 509, in dispatch
    response = self.handle_exception(exc)
               ^^^^^^^^^^^^^^^^^^^^^^^^^^
  File "C:\Users\Admin\AppData\Local\Programs\Python\Python311\Lib\site-packages\rest_framework\views.py", line 469, in handle_exception
    self.raise_uncaught_exception(exc)
  File "C:\Users\Admin\AppData\Local\Programs\Python\Python311\Lib\site-packages\rest_framework\views.py", line 480, in raise_uncaught_exception
    raise exc
  File "C:\Users\Admin\AppData\Local\Programs\Python\Python311\Lib\site-packages\rest_framework\views.py", line 506, in dispatch
    response = handler(request, *args, **kwargs)
               ^^^^^^^^^^^^^^^^^^^^^^^^^^^^^^^^^
  File "D:\drf\project task\log crud task 4\project1\backend\app1\views.py", line 23, in create
    serializer.save()
  File "C:\Users\Admin\AppData\Local\Programs\Python\Python311\Lib\site-packages\rest_framework\serializers.py", line 212, in save
    self.instance = self.create(validated_data)
                    ^^^^^^^^^^^^^^^^^^^^^^^^^^^
  File "C:\Users\Admin\AppData\Local\Programs\Python\Python311\Lib\site-packages\rest_framework\serializers.py", line 962, in create
    instance = ModelClass._default_manager.create(**validated_data)
               ^^^^^^^^^^^^^^^^^^^^^^^^^^^^^^^^^^^^^^^^^^^^^^^^^^^^
  File "C:\Users\Admin\AppData\Local\Programs\Python\Python311\Lib\site-packages\django\db\models\manager.py", line 87, in manager_method
    return getattr(self.get_queryset(), name)(*args, **kwargs)
           ^^^^^^^^^^^^^^^^^^^^^^^^^^^^^^^^^^^^^^^^^^^^^^^^^^^
  File "C:\Users\Admin\AppData\Local\Programs\Python\Python311\Lib\site-packages\django\db\models\query.py", line 658, in create
    obj.save(force_insert=True, using=self.db)
  File "C:\Users\Admin\AppData\Local\Programs\Python\Python311\Lib\site-packages\django\db\models\base.py", line 814, in save
    self.save_base(
  File "C:\Users\Admin\AppData\Local\Programs\Python\Python311\Lib\site-packages\django\db\models\base.py", line 877, in save_base
    updated = self._save_table(
              ^^^^^^^^^^^^^^^^^
  File "C:\Users\Admin\AppData\Local\Programs\Python\Python311\Lib\site-packages\django\db\models\base.py", line 1020, in _save_table
    results = self._do_insert(
              ^^^^^^^^^^^^^^^^
  File "C:\Users\Admin\AppData\Local\Programs\Python\Python311\Lib\site-packages\django\db\models\base.py", line 1061, in _do_insert
    return manager._insert(
           ^^^^^^^^^^^^^^^^
  File "C:\Users\Admin\AppData\Local\Programs\Python\Python311\Lib\site-packages\django\db\models\manager.py", line 87, in manager_method
    return getattr(self.get_queryset(), name)(*args, **kwargs)
           ^^^^^^^^^^^^^^^^^^^^^^^^^^^^^^^^^^^^^^^^^^^^^^^^^^^
  File "C:\Users\Admin\AppData\Local\Programs\Python\Python311\Lib\site-packages\django\db\models\query.py", line 1805, in _insert
    return query.get_compiler(using=using).execute_sql(returning_fields)
           ^^^^^^^^^^^^^^^^^^^^^^^^^^^^^^^^^^^^^^^^^^^^^^^^^^^^^^^^^^^^^
  File "C:\Users\Admin\AppData\Local\Programs\Python\Python311\Lib\site-packages\django\db\models\sql\compiler.py", line 1822, in execute_sql
    cursor.execute(sql, params)
  File "C:\Users\Admin\AppData\Local\Programs\Python\Python311\Lib\site-packages\django\db\backends\utils.py", line 102, in execute
    return super().execute(sql, params)
           ^^^^^^^^^^^^^^^^^^^^^^^^^^^^
  File "C:\Users\Admin\AppData\Local\Programs\Python\Python311\Lib\site-packages\django\db\backends\utils.py", line 67, in execute
    return self._execute_with_wrappers(
           ^^^^^^^^^^^^^^^^^^^^^^^^^^^^
  File "C:\Users\Admin\AppData\Local\Programs\Python\Python311\Lib\site-packages\django\db\backends\utils.py", line 80, in _execute_with_wrappers
    return executor(sql, params, many, context)
           ^^^^^^^^^^^^^^^^^^^^^^^^^^^^^^^^^^^^
  File "C:\Users\Admin\AppData\Local\Programs\Python\Python311\Lib\site-packages\django\db\backends\utils.py", line 89, in _execute
    return self.cursor.execute(sql, params)
           ^^^^^^^^^^^^^^^^^^^^^^^^^^^^^^^^
  File "C:\Users\Admin\AppData\Local\Programs\Python\Python311\Lib\site-packages\django\db\backends\mysql\base.py", line 80, in execute
    raise IntegrityError(*tuple(e.args))
django.db.utils.IntegrityError: (1048, "Column 'gender' cannot be null")
ERROR 2023-10-19 18:08:32,269 basehttp "POST /v1/student/ HTTP/1.1" 500 192467
WARNING 2023-10-19 19:03:29,016 log Method Not Allowed: /v1/student/3/
WARNING 2023-10-19 19:03:29,017 basehttp "GET /v1/student/3/ HTTP/1.1" 405 40
WARNING 2023-10-19 19:03:29,022 log Method Not Allowed: /v1/student/3/
WARNING 2023-10-19 19:03:29,022 basehttp "GET /v1/student/3/ HTTP/1.1" 405 40
WARNING 2023-10-19 19:03:39,291 log Method Not Allowed: /v1/student/3/
WARNING 2023-10-19 19:03:39,291 basehttp "GET /v1/student/3/ HTTP/1.1" 405 40
WARNING 2023-10-19 19:03:39,301 log Method Not Allowed: /v1/student/3/
WARNING 2023-10-19 19:03:39,302 basehttp "GET /v1/student/3/ HTTP/1.1" 405 40
WARNING 2023-10-19 19:06:57,021 log Method Not Allowed: /v1/student/3/
WARNING 2023-10-19 19:06:57,027 basehttp "GET /v1/student/3/ HTTP/1.1" 405 40
WARNING 2023-10-19 19:07:24,568 log Method Not Allowed: /v1/student/1/
WARNING 2023-10-19 19:07:24,576 basehttp "GET /v1/student/1/ HTTP/1.1" 405 40
WARNING 2023-10-19 19:07:29,244 log Method Not Allowed: /v1/student/1/
WARNING 2023-10-19 19:07:29,244 basehttp "GET /v1/student/1/ HTTP/1.1" 405 40
ERROR 2023-10-19 19:07:43,164 log Internal Server Error: /v1/student/1
Traceback (most recent call last):
  File "C:\Users\Admin\AppData\Local\Programs\Python\Python311\Lib\site-packages\django\core\handlers\exception.py", line 55, in inner
    response = get_response(request)
               ^^^^^^^^^^^^^^^^^^^^^
  File "C:\Users\Admin\AppData\Local\Programs\Python\Python311\Lib\site-packages\django\utils\deprecation.py", line 136, in __call__
    response = self.process_response(request, response)
               ^^^^^^^^^^^^^^^^^^^^^^^^^^^^^^^^^^^^^^^^
  File "C:\Users\Admin\AppData\Local\Programs\Python\Python311\Lib\site-packages\django\middleware\common.py", line 108, in process_response
    return self.response_redirect_class(self.get_full_path_with_slash(request))
                                        ^^^^^^^^^^^^^^^^^^^^^^^^^^^^^^^^^^^^^^
  File "C:\Users\Admin\AppData\Local\Programs\Python\Python311\Lib\site-packages\django\middleware\common.py", line 87, in get_full_path_with_slash
    raise RuntimeError(
RuntimeError: You called this URL via POST, but the URL doesn't end in a slash and you have APPEND_SLASH set. Django can't redirect to the slash URL while maintaining POST data. Change your form to point to 127.0.0.1:8000/v1/student/1/ (note the trailing slash), or set APPEND_SLASH=False in your Django settings.
ERROR 2023-10-19 19:07:43,179 basehttp "POST /v1/student/1 HTTP/1.1" 500 71496
WARNING 2023-10-19 19:07:58,581 log Method Not Allowed: /v1/student/1/
WARNING 2023-10-19 19:07:58,581 basehttp "POST /v1/student/1/ HTTP/1.1" 405 41
WARNING 2023-10-19 19:08:11,113 log Method Not Allowed: /v1/student/2/
WARNING 2023-10-19 19:08:11,113 basehttp "GET /v1/student/2/ HTTP/1.1" 405 40
WARNING 2023-10-19 19:08:27,022 log Method Not Allowed: /v1/student/3/
WARNING 2023-10-19 19:08:27,026 basehttp "GET /v1/student/3/ HTTP/1.1" 405 40
WARNING 2023-10-19 19:08:33,522 log Method Not Allowed: /v1/student/3/
WARNING 2023-10-19 19:08:33,523 basehttp "GET /v1/student/3/ HTTP/1.1" 405 40
WARNING 2023-10-19 19:09:22,733 log Method Not Allowed: /v1/student/3/
WARNING 2023-10-19 19:09:22,735 basehttp "GET /v1/student/3/ HTTP/1.1" 405 40
WARNING 2023-10-19 19:09:22,737 log Method Not Allowed: /v1/student/3/
WARNING 2023-10-19 19:09:22,742 basehttp "GET /v1/student/3/ HTTP/1.1" 405 40
WARNING 2023-10-19 19:09:37,801 log Method Not Allowed: /v1/student/3/
WARNING 2023-10-19 19:09:37,802 basehttp "GET /v1/student/3/ HTTP/1.1" 405 40
WARNING 2023-10-19 19:10:05,737 log Method Not Allowed: /v1/student/3/
WARNING 2023-10-19 19:10:05,742 basehttp "GET /v1/student/3/ HTTP/1.1" 405 40
WARNING 2023-10-19 19:10:05,753 log Method Not Allowed: /v1/student/3/
WARNING 2023-10-19 19:10:05,756 basehttp "GET /v1/student/3/ HTTP/1.1" 405 40
WARNING 2023-10-19 20:06:18,135 log Method Not Allowed: /v1/student/2/
WARNING 2023-10-19 20:06:18,137 basehttp "GET /v1/student/2/ HTTP/1.1" 405 40
WARNING 2023-10-19 20:06:18,142 log Method Not Allowed: /v1/student/2/
WARNING 2023-10-19 20:06:18,143 basehttp "GET /v1/student/2/ HTTP/1.1" 405 40
WARNING 2023-10-19 20:07:06,505 log Method Not Allowed: /v1/student/3/
WARNING 2023-10-19 20:07:06,506 basehttp "GET /v1/student/3/ HTTP/1.1" 405 40
WARNING 2023-10-19 20:10:14,954 log Method Not Allowed: /v1/student/2/
WARNING 2023-10-19 20:10:14,957 basehttp "GET /v1/student/2/ HTTP/1.1" 405 40
WARNING 2023-10-19 20:10:14,959 log Method Not Allowed: /v1/student/2/
WARNING 2023-10-19 20:10:14,959 basehttp "GET /v1/student/2/ HTTP/1.1" 405 40
WARNING 2023-10-19 20:16:05,470 log Method Not Allowed: /v1/student/2/
WARNING 2023-10-19 20:16:05,470 basehttp "GET /v1/student/2/ HTTP/1.1" 405 40
WARNING 2023-10-19 20:16:09,465 log Method Not Allowed: /v1/student/2/
WARNING 2023-10-19 20:16:09,465 basehttp "GET /v1/student/2/ HTTP/1.1" 405 40
WARNING 2023-10-19 20:16:19,231 log Method Not Allowed: /v1/student/3/
WARNING 2023-10-19 20:16:19,234 basehttp "GET /v1/student/3/ HTTP/1.1" 405 40
WARNING 2023-10-19 20:16:19,236 log Method Not Allowed: /v1/student/3/
WARNING 2023-10-19 20:16:19,236 basehttp "GET /v1/student/3/ HTTP/1.1" 405 40
WARNING 2023-10-19 20:17:01,462 log Method Not Allowed: /v1/student/3/
WARNING 2023-10-19 20:17:01,467 basehttp "GET /v1/student/3/ HTTP/1.1" 405 40
WARNING 2023-10-19 20:22:41,477 log Method Not Allowed: /v1/student/3/
WARNING 2023-10-19 20:22:41,480 basehttp "GET /v1/student/3/ HTTP/1.1" 405 40
WARNING 2023-10-19 20:22:56,265 log Method Not Allowed: /v1/student/3/
WARNING 2023-10-19 20:22:56,269 basehttp "GET /v1/student/3/ HTTP/1.1" 405 40
WARNING 2023-10-19 20:22:56,272 log Method Not Allowed: /v1/student/3/
WARNING 2023-10-19 20:22:56,276 basehttp "GET /v1/student/3/ HTTP/1.1" 405 40
WARNING 2023-10-19 20:29:01,457 log Method Not Allowed: /v1/student/3/
WARNING 2023-10-19 20:29:01,459 basehttp "GET /v1/student/3/ HTTP/1.1" 405 40
WARNING 2023-10-19 20:29:15,317 log Method Not Allowed: /v1/student/2/
WARNING 2023-10-19 20:29:15,319 basehttp "GET /v1/student/2/ HTTP/1.1" 405 40
WARNING 2023-10-19 20:29:15,324 log Method Not Allowed: /v1/student/2/
WARNING 2023-10-19 20:29:15,327 basehttp "GET /v1/student/2/ HTTP/1.1" 405 40
WARNING 2023-10-19 20:30:19,446 log Method Not Allowed: /v1/student/2/
WARNING 2023-10-19 20:30:19,446 basehttp "GET /v1/student/2/ HTTP/1.1" 405 40
WARNING 2023-10-19 20:31:09,759 log Method Not Allowed: /v1/student/2/
WARNING 2023-10-19 20:31:09,763 basehttp "GET /v1/student/2/ HTTP/1.1" 405 40
WARNING 2023-10-19 20:31:29,810 log Method Not Allowed: /v1/student/3/
WARNING 2023-10-19 20:31:29,815 basehttp "GET /v1/student/3/ HTTP/1.1" 405 40
WARNING 2023-10-19 20:31:29,818 log Method Not Allowed: /v1/student/3/
WARNING 2023-10-19 20:31:29,818 basehttp "GET /v1/student/3/ HTTP/1.1" 405 40
WARNING 2023-10-19 20:32:40,993 log Not Found: /v1/students/3/
WARNING 2023-10-19 20:32:40,993 basehttp "PUT /v1/students/3/ HTTP/1.1" 404 3319
WARNING 2023-10-19 20:34:02,844 log Method Not Allowed: /v1/student/5/
WARNING 2023-10-19 20:34:02,844 basehttp "GET /v1/student/5/ HTTP/1.1" 405 40
WARNING 2023-10-19 20:34:02,848 log Method Not Allowed: /v1/student/5/
WARNING 2023-10-19 20:34:02,851 basehttp "GET /v1/student/5/ HTTP/1.1" 405 40
WARNING 2023-10-19 20:34:13,473 log Method Not Allowed: /v1/student/5/
WARNING 2023-10-19 20:34:13,476 basehttp "GET /v1/student/5/ HTTP/1.1" 405 40
WARNING 2023-10-19 20:34:13,482 log Method Not Allowed: /v1/student/5/
WARNING 2023-10-19 20:34:13,483 basehttp "GET /v1/student/5/ HTTP/1.1" 405 40
WARNING 2023-10-19 20:34:39,315 log Method Not Allowed: /v1/student/5/
WARNING 2023-10-19 20:34:39,317 basehttp "GET /v1/student/5/ HTTP/1.1" 405 40
WARNING 2023-10-19 20:34:39,323 log Method Not Allowed: /v1/student/5/
WARNING 2023-10-19 20:34:39,327 basehttp "GET /v1/student/5/ HTTP/1.1" 405 40
WARNING 2023-10-19 20:39:20,450 log Method Not Allowed: /v1/student/5/
WARNING 2023-10-19 20:39:20,450 basehttp "GET /v1/student/5/ HTTP/1.1" 405 40
WARNING 2023-10-19 20:40:11,449 log Method Not Allowed: /v1/student/5/
WARNING 2023-10-19 20:40:11,449 basehttp "GET /v1/student/5/ HTTP/1.1" 405 40
WARNING 2023-10-19 20:40:26,933 log Method Not Allowed: /v1/student/4/
WARNING 2023-10-19 20:40:26,933 basehttp "GET /v1/student/4/ HTTP/1.1" 405 40
WARNING 2023-10-19 20:40:26,938 log Method Not Allowed: /v1/student/4/
WARNING 2023-10-19 20:40:26,940 basehttp "GET /v1/student/4/ HTTP/1.1" 405 40
WARNING 2023-10-19 20:44:57,321 log Method Not Allowed: /v1/student/5/
WARNING 2023-10-19 20:44:57,322 basehttp "GET /v1/student/5/ HTTP/1.1" 405 40
WARNING 2023-10-19 20:44:57,328 log Method Not Allowed: /v1/student/5/
WARNING 2023-10-19 20:44:57,330 basehttp "GET /v1/student/5/ HTTP/1.1" 405 40
WARNING 2023-10-19 20:54:37,480 log Method Not Allowed: /v1/student/3/
WARNING 2023-10-19 20:54:37,480 basehttp "GET /v1/student/3/ HTTP/1.1" 405 40
WARNING 2023-10-19 20:54:37,495 log Method Not Allowed: /v1/student/3/
WARNING 2023-10-19 20:54:37,500 basehttp "GET /v1/student/3/ HTTP/1.1" 405 40
WARNING 2023-10-19 20:54:46,830 log Method Not Allowed: /v1/student/3/
WARNING 2023-10-19 20:54:46,837 basehttp "GET /v1/student/3/ HTTP/1.1" 405 40
WARNING 2023-10-19 20:54:46,843 log Method Not Allowed: /v1/student/3/
WARNING 2023-10-19 20:54:46,845 basehttp "GET /v1/student/3/ HTTP/1.1" 405 40
WARNING 2023-10-19 20:55:14,985 log Bad Request: /v1/student/3/
WARNING 2023-10-19 20:55:14,985 basehttp "PUT /v1/student/3/ HTTP/1.1" 400 37
WARNING 2023-10-19 20:55:48,769 log Method Not Allowed: /v1/student/3/
WARNING 2023-10-19 20:55:48,770 basehttp "GET /v1/student/3/ HTTP/1.1" 405 40
WARNING 2023-10-19 20:55:48,776 log Method Not Allowed: /v1/student/3/
WARNING 2023-10-19 20:55:48,777 basehttp "GET /v1/student/3/ HTTP/1.1" 405 40
WARNING 2023-10-19 20:55:54,566 log Method Not Allowed: /v1/student/3/
WARNING 2023-10-19 20:55:54,570 basehttp "GET /v1/student/3/ HTTP/1.1" 405 40
WARNING 2023-10-19 20:55:54,575 log Method Not Allowed: /v1/student/3/
WARNING 2023-10-19 20:55:54,576 basehttp "GET /v1/student/3/ HTTP/1.1" 405 40
WARNING 2023-10-19 21:00:22,783 log Not Found: /v1/students/3/
WARNING 2023-10-19 21:00:22,785 basehttp "GET /v1/students/3/ HTTP/1.1" 404 3319
WARNING 2023-10-19 21:00:22,805 log Not Found: /v1/students/3/
WARNING 2023-10-19 21:00:22,805 basehttp "GET /v1/students/3/ HTTP/1.1" 404 3319
WARNING 2023-10-19 21:00:59,989 log Not Found: /v1/students/3/
WARNING 2023-10-19 21:00:59,989 basehttp "GET /v1/students/3/ HTTP/1.1" 404 3319
WARNING 2023-10-19 21:00:59,997 log Not Found: /v1/students/3/
WARNING 2023-10-19 21:01:00,003 basehttp "GET /v1/students/3/ HTTP/1.1" 404 3319
WARNING 2023-10-19 21:01:11,087 log Not Found: /v1/students/3/
WARNING 2023-10-19 21:01:11,087 basehttp "DELETE /v1/students/3/ HTTP/1.1" 404 3322
WARNING 2023-10-19 21:01:19,921 log Not Found: /v1/students/3/
WARNING 2023-10-19 21:01:19,921 basehttp "GET /v1/students/3/ HTTP/1.1" 404 3319
WARNING 2023-10-19 21:01:19,937 log Not Found: /v1/students/3/
WARNING 2023-10-19 21:01:19,939 basehttp "GET /v1/students/3/ HTTP/1.1" 404 3319
WARNING 2023-10-19 21:03:43,676 log Not Found: /v1/students/3/
WARNING 2023-10-19 21:03:43,676 basehttp "GET /v1/students/3/ HTTP/1.1" 404 3319
WARNING 2023-10-19 21:03:43,696 log Not Found: /v1/students/3/
WARNING 2023-10-19 21:03:43,701 basehttp "GET /v1/students/3/ HTTP/1.1" 404 3319
WARNING 2023-10-19 21:04:01,177 log Not Found: /v1/students/3/
WARNING 2023-10-19 21:04:01,177 basehttp "GET /v1/students/3/ HTTP/1.1" 404 3319
WARNING 2023-10-19 21:04:01,194 log Not Found: /v1/students/3/
WARNING 2023-10-19 21:04:01,196 basehttp "GET /v1/students/3/ HTTP/1.1" 404 3319
WARNING 2023-10-19 21:04:06,152 log Not Found: /v1/students/3/
WARNING 2023-10-19 21:04:06,155 basehttp "DELETE /v1/students/3/ HTTP/1.1" 404 3322
WARNING 2023-10-19 21:04:55,828 log Not Found: /v1/students/3/
WARNING 2023-10-19 21:04:55,828 basehttp "GET /v1/students/3/ HTTP/1.1" 404 3319
WARNING 2023-10-19 21:04:55,846 log Not Found: /v1/students/3/
WARNING 2023-10-19 21:04:55,852 basehttp "GET /v1/students/3/ HTTP/1.1" 404 3319
WARNING 2023-10-19 21:05:53,291 log Method Not Allowed: /v1/student/3/
WARNING 2023-10-19 21:05:53,294 basehttp "GET /v1/student/3/ HTTP/1.1" 405 40
WARNING 2023-10-19 21:05:53,304 log Method Not Allowed: /v1/student/3/
WARNING 2023-10-19 21:05:53,309 basehttp "GET /v1/student/3/ HTTP/1.1" 405 40
WARNING 2023-10-19 21:06:20,531 log Not Found: /v1/students/3/
WARNING 2023-10-19 21:06:20,531 basehttp "DELETE /v1/students/3/ HTTP/1.1" 404 3322
WARNING 2023-10-19 21:09:50,197 log Method Not Allowed: /v1/student/3/
WARNING 2023-10-19 21:09:50,198 basehttp "GET /v1/student/3/ HTTP/1.1" 405 40
WARNING 2023-10-19 21:09:50,202 log Method Not Allowed: /v1/student/3/
WARNING 2023-10-19 21:09:50,204 basehttp "GET /v1/student/3/ HTTP/1.1" 405 40
WARNING 2023-10-19 21:10:40,055 log Method Not Allowed: /v1/student/3/
WARNING 2023-10-19 21:10:40,059 basehttp "GET /v1/student/3/ HTTP/1.1" 405 40
WARNING 2023-10-19 21:10:40,067 log Method Not Allowed: /v1/student/3/
WARNING 2023-10-19 21:10:40,067 basehttp "GET /v1/student/3/ HTTP/1.1" 405 40
WARNING 2023-10-19 21:10:47,751 log Not Found: /v1/students/3/
WARNING 2023-10-19 21:10:47,751 basehttp "DELETE /v1/students/3/ HTTP/1.1" 404 3322
WARNING 2023-10-19 21:10:53,292 log Method Not Allowed: /v1/student/3/
WARNING 2023-10-19 21:10:53,295 basehttp "GET /v1/student/3/ HTTP/1.1" 405 40
WARNING 2023-10-19 21:10:53,300 log Method Not Allowed: /v1/student/3/
WARNING 2023-10-19 21:10:53,303 basehttp "GET /v1/student/3/ HTTP/1.1" 405 40
WARNING 2023-10-19 21:10:57,556 log Not Found: /v1/students/3/
WARNING 2023-10-19 21:10:57,562 basehttp "DELETE /v1/students/3/ HTTP/1.1" 404 3322
WARNING 2023-10-19 21:14:50,962 log Method Not Allowed: /v1/student/3/
WARNING 2023-10-19 21:14:50,962 basehttp "GET /v1/student/3/ HTTP/1.1" 405 40
WARNING 2023-10-19 21:14:50,975 log Method Not Allowed: /v1/student/3/
WARNING 2023-10-19 21:14:50,975 basehttp "GET /v1/student/3/ HTTP/1.1" 405 40
WARNING 2023-10-19 21:15:52,529 log Method Not Allowed: /v1/student/6/
WARNING 2023-10-19 21:15:52,532 basehttp "GET /v1/student/6/ HTTP/1.1" 405 40
WARNING 2023-10-19 21:15:52,540 log Method Not Allowed: /v1/student/6/
WARNING 2023-10-19 21:15:52,544 basehttp "GET /v1/student/6/ HTTP/1.1" 405 40
WARNING 2023-10-19 21:22:13,555 log Method Not Allowed: /v1/student/3/
WARNING 2023-10-19 21:22:13,558 basehttp "GET /v1/student/3/ HTTP/1.1" 405 40
WARNING 2023-10-19 21:22:13,564 log Method Not Allowed: /v1/student/3/
WARNING 2023-10-19 21:22:13,567 basehttp "GET /v1/student/3/ HTTP/1.1" 405 40
WARNING 2023-10-19 21:22:18,269 log Not Found: /v1/students/3/
WARNING 2023-10-19 21:22:18,273 basehttp "DELETE /v1/students/3/ HTTP/1.1" 404 3322
WARNING 2023-10-19 21:46:41,887 log Method Not Allowed: /v1/student/3/
WARNING 2023-10-19 21:46:41,887 basehttp "GET /v1/student/3/ HTTP/1.1" 405 40
WARNING 2023-10-19 21:46:41,899 log Method Not Allowed: /v1/student/3/
WARNING 2023-10-19 21:46:41,903 basehttp "GET /v1/student/3/ HTTP/1.1" 405 40
WARNING 2023-10-19 21:49:56,849 log Method Not Allowed: /v1/student/3/
WARNING 2023-10-19 21:49:56,849 basehttp "GET /v1/student/3/ HTTP/1.1" 405 7243
WARNING 2023-10-19 21:49:57,139 log Not Found: /favicon.ico
WARNING 2023-10-19 21:49:57,139 basehttp "GET /favicon.ico HTTP/1.1" 404 2214
